Workbook

Sheet default_1
A1: Author Full Names | B1: Journal ISO Abbreviation | C1: Publication Date | D1: Publication Year | E1: Cites | F1: DOI | G1: ID | H1: Transport mode | I1: Multimodal components | J1: Total number transactions | K1: Days | L1: Year(s) | M1: Study Area | N1: Structure | O1: Only dataset | P1: Main dataset | Q1: Supplementary datasets | R1: Data accessibility | S1: Analytical category | T1: Analytical subcategory | U1: Techniques | V1: Methods | W1: Derived | X1: Derived from | Y1: Preprocessed | Z1: Features | AA1: Validation metrics | AB1: Tools | AC1: Domain
A2: Rodrigues, Filipe; Borysov, Stanislav S.; Ribeiro, Bernardete; Pereira, Francisco C. | B2: IEEE Trans. Pattern Anal. Mach. Intell. | C2: NOV | D2: 2017 | E2: =VLOOKUP(default_1!F118,Hoja1!$AD$1:$AE$176,2,FALSE) -> 48 | F2: 10.1109/TPAMI.2016.2635136 | G2: P001 | H2: Subway | J2: 2700000 | K2: 151 | L2: 2012-2013 | M2: Singapore | N2: Closed | O2: 0 | P2: 0 | Q2: Events | R2: 0 | S2: Demand forecasting | T2: Spatio-temporal | U2: Bayesian Additive Model-Gaussian Process;LDA | V2: Probability techniques;Natural language processing | W2: 1 | X2: Bayesian additive model; Gaussian process | Y2: 1 | AA2: RAE;Correlation coefficient;R² | AB2: Julia | AC2: Transportation
A3: Tang, Liyang; Zhao, Yang; Tsui, Kwok Leung; He, Yuxin; Pan, Liwei | B3: Appl. Sci.-Basel | C3: AUG | D3: 2020 | E3: =VLOOKUP(default_1!F71,Hoja1!$AD$1:$AE$176,2,FALSE) -> 6 | F3: 10.3390/app10165606 | G3: P002 | H3: Subway | J3: 330000000 | K3: 122 | L3: 2013 | M3: Shenzhen, China | N3: Closed | O3: 0 | P3: 1 | Q3: Regulation;POI;Social/Demographic/Economic | R3: 0 | S3: Classification | T3: Spatio-temporal | U3: k-means;ProClus;HDDC;Cluster refinement framework with Cluster Member Based Stability;PCA | V3: Clustering;Clustering;Clustering;Clustering;Dimensionality reduction | W3: 0 | Y3: 1 | Z3: SFD | AA3: Moran's I;Lagrange multiplier test | AB3: R | AC3: Urban planning
A4: Zhang, Yang; Cheng, Tao | B4: IEEE Trans. Intell. Transp. Syst. | C4: FEB | D4: 2020 | E4: =VLOOKUP(default_1!F86,Hoja1!$AD$1:$AE$176,2,FALSE) -> 2 | F4: 10.1109/TITS.2019.2896460 | G4: P003 | H4: Multimodal | I4: Bus;Subway | J4: 2720000 | L4: 2013 | M4: London, UK | N4: Open-Closed | O4: 0 | P4: 0 | Q4: Survey | R4: 0 | S4: Classification | T4: Social/Economic/Demographic | U4: Thresholding Multi-Channel Convolutional Neural Network | V4: Deep learning | W4: 0 | Y4: 1 | AA4: PPV;TPR;F-Score | AB4: R | AC4: Socio-economic / demographic
A5: Hosoe, Mio; Kuwano, Masashi; Moriyama, Taku | B5: J. Big Data | C5: JAN 7 | D5: 2021 | E5: =VLOOKUP(default_1!F57,Hoja1!$AD$1:$AE$176,2,FALSE) -> 23 | F5: 10.1186/s40537-020-00402-w | G5: P004 | H5: Train | J5: 9008709 | K5: 455 | L5: 2013-2015 | M5: Kagawa Prefecture, Japan | N5: Closed | O5: 1 | P5: 1 | R5: 0 | S5: Pattern analysis | T5: Passenger | U5: Data polishing | V5: Clustering | W5: 1 | X5: Uno et al. 2016 | Y5: 0 | AA5: Thresholds | AC5: Transportation
A6: Le-Minh Kieu; Bhaskar, Ashish; Chung, Edward | B6: Transp. Res. Pt. C-Emerg. Technol. | C6: SEP | D6: 2015 | E6: =VLOOKUP(default_1!F134,Hoja1!$AD$1:$AE$176,2,FALSE) -> 2 | F6: 10.1016/j.trc.2015.03.033 | G6: P005 | H6: Multimodal | I6: Bus;Train;Ferry | J6: 34800000 | K6: 122 | L6: 2012 | M6: South East Queensland, Australia | N6: Closed | O6: 1 | P6: 1 | R6: 0 | S6: Classification | T6: Spatio-temporal | U6: WS-DBSCAN | V6: Clustering | W6: 1 | X6: DBSCAN | Y6: 0 | AA6: Performance | AC6: Transportation
A7: Wang, Wenjing; Wang, Yihong; Correia, Goncalo Homem de Almeida; Chen, Yusen | B7: J. Adv. Transp. | C7: DEC 7 | D7: 2020 | E7: =VLOOKUP(default_1!F64,Hoja1!$AD$1:$AE$176,2,FALSE) -> 14 | F7: 10.1155/2020/6659931 | G7: P006 | H7: Multimodal | I7: Bus;Subway | J7: 120000000 | K7: 8 | L7: 2017 | M7: Beijing, China | N7: Closed | O7: 0 | P7: 0 | Q7: Network;POI | R7: 0 | S7: Passengers flow | T7: Transfer | U7: Gravity-based model;Regression model | V7: Gravity-based model;Regression | W7: 0 | Y7: 1 | Z7: Transfer flow, transfer accesability, transfer time, bus stops per metro station, bus lines per bus stop | AA7: R²;F-Score | AC7: Transportation
A8: Shalit, Nadav; Fire, Michael; Ben-Elia, Eran | B8: Public Transport | C8: JUN | D8: 2023 | E8: =VLOOKUP(default_1!F40,Hoja1!$AD$1:$AE$176,2,FALSE) -> 4 | F8: 10.1007/s12469-022-00309-0 | G8: P007 | H8: Multimodal | I8: Bus;Train | J8: 1000000 | K8: 30 | L8: 2018 | M8: Beer Sheva, Israel;Kiryat Gat, Israel | N8: Open-Closed | O8: 0 | P8: 0 | Q8: Transit Feed;Layers | R8: 0 | S8: Data preprocessing | T8: Data imputation | U8: SHAP;Random Forest;Logistic Regression;XGBoost | V8: Game theory;Classification;Classification;Classification | W8: 0 | Y8: 1 | Z8: Addresses_average;Street_light_average;Traffic_Lights_average;Number_of_points;Average_distance_per_stop;Average_time_per_stop;Average_points_to_stops;Time_diff_of_trip;Time_from_boarding_to_last_stop;Time_from_departure_to_boarding;Predicted_sequence;Hourly_expected_lateness;Boardingtime_Seconds_from_midnight;Boardingtime_weekday;Is_weekend | AA8: Accuracy;TPR;PPV;F-Score;AUC;RMSE;Shapely values | AC8: Transportation
A9: Shin, Yonggeun; Kim, Dong-Kyu; Kim, Eui-Jin | B9: J. Transp. Geogr. | C9: DEC | D9: 2022 | E9: =VLOOKUP(default_1!F7,Hoja1!$AD$1:$AE$176,2,FALSE) -> 13 | F9: 10.1016/j.jtrangeo.2022.103459 | G9: P008 | H9: Multimodal | I9: Bus;Subway | J9: 80000000 | K9: 4 | L9: 2017 | M9: Seoul, South Korea | N9: Open-Closed | O9: 0 | P9: 0 | Q9: Land use | R9: 0 | S9: Classification | T9: Spatio-temporal | U9: Hidden Markov Model;k-means | V9: Stochastic modeling;Clustering | W9: 0 | Y9: 1 | Z9: activity sequence | AA9: AIC;BIC | AC9: Urban planning
A10: Lee, Haengju; Eun, Yongsoon | B10: IEEE Trans. Intell. Transp. Syst. | C10: DEC | D10: 2022 | E10: =VLOOKUP(default_1!F9,Hoja1!$AD$1:$AE$176,2,FALSE) -> 2 | F10: 10.1109/TITS.2022.3203705 | G10: P010 | H10: Subway | J10: 9663319 | K10: 30 | L10: 2018 | M10: Daegu, South Korea | N10: Closed | O10: 0 | P10: 1 | Q10: Layers | R10: 0 | S10: Demand forecasting | T10: Marketing | U10: Linear programming;Dynamic programming;Poisson distribution | V10: Optimization;Optimization;Clustering | W10: 0 | Y10: 1 | AA10: Performance | AC10: Marketing
A11: Liyanage, Sohani; Abduljabbar, Rusul; Dia, Hussein; Tsai, Pei -Wei | B11: J. Urban Manag. | C11: SEP | D11: 2022 | E11: =VLOOKUP(default_1!F13,Hoja1!$AD$1:$AE$176,2,FALSE) -> 11 | F11: 10.1016/j.jum.2022.05.002 | G11: P011 | H11: Bus | J11: 715375 | K11: 31 | L11: 2018 | M11: Melbourne, Australia | N11: Closed | O11: 1 | P11: 1 | R11: 0 | S11: Demand forecasting | T11: Spatio-temporal | U11: Long short-term memory;Bidirectional Long short-term memory;Unidirectional Long short-term memory | V11: Deep learning;Deep learning;Deep learning | W11: 0 | Y11: 1 | AA11: MAPE;MAE;RMSE;R² | AB11: Matlab | AC11: Transportation
A12: Wang, Xueqin; Xu, Xinyue; Wu, Yuankai; Liu, Jun | B12: Soft Comput. | C12: JUN | D12: 2022 | E12: =VLOOKUP(default_1!F23,Hoja1!$AD$1:$AE$176,2,FALSE) -> 14 | F12: 10.1007/s00500-022-07025-8 | G12: P012 | H12: Subway | K12: 73 | L12: 2019 | M12: Beijing, China | N12: Closed | O12: 1 | P12: 1 | R12: 0 | S12: Demand forecasting | T12: Flow | U12: STGGA | V12: Deep learning | W12: 1 | X12: GCN;GRU | Y12: 1 | AA12: RMSE;accuracy;R²;Friedman test;Wilcoxon signed-rank test | AB12: TensorFlow | AC12: Transportation
A13: Lin, Pengfei; Weng, Jiancheng; Brands, Devi K.; Qian, Huimin; Yin, Baocai | B13: IET Intell. Transp. Syst. | C13: DEC 27 | D13: 2020 | E13: =VLOOKUP(default_1!F61,Hoja1!$AD$1:$AE$176,2,FALSE) -> 2 | F13: 10.1049/iet-its.2020.0469 | G13: P013 | H13: Multimodal | I13: Bus;Subway | J13: 3650000000 | K13: 365 | L13: 2018-2019 | M13: Beijing, China | N13: Closed | O13: 0 | P13: 0 | Q13: Meteorological;POI;Network;Land use;Layers | R13: 0 | S13: Pattern analysis | T13: Meteorological | U13: LightGBM | V13: Regression | W13: 0 | Y13: 0 | Z13: average temperature;relative humidity;average wind speed;rainfall;AQI;snowfall;month;weekend/public holiday;residence;office;distance from CBD;education;commercial;hospital;bus;land use mix;subway;scenic spot;transport hub | AA13: R²;MAE;RMSE;Running time | AC13: Transportation
A14: Sun, Feng; Su, Wenheng; Liu, Weixuan; Cao, Hui; Guo, Dong; Zhu, Ye | B14: J. Electr. Comput. Eng. | D14: 2018 | E14: =VLOOKUP(default_1!F115,Hoja1!$AD$1:$AE$176,2,FALSE) -> 1 | F14: 10.1155/2018/2975615 | G14: P014 | H14: Bus | J14: 10658558 | K14: 7 | L14: 2017 | M14: Qingdao, China | N14: Open | O14: 1 | P14: 1 | R14: 0 | S14: Demand forecasting | T14: Spatio-temporal | U14: ARIMA;NARX | V14: Time series analysis;Time series analysis | W14: 0 | Y14: 1 | AA14: Wilcoxon signed-rank test;acuracy;MSE;R;Relative error | AB14: Matlab;SQL | AC14: Transportation
A15: Briand, Anne-Sarah; Come, Etienne; Trepanier, Martin; Oukhellou, Latifa | B15: Transp. Res. Pt. C-Emerg. Technol. | C15: JUN | D15: 2017 | E15: =VLOOKUP(default_1!F120,Hoja1!$AD$1:$AE$176,2,FALSE) -> 2 | F15: 10.1016/j.trc.2017.03.021 | G15: P015 | H15: Bus | J15: 3492310 | K15: 140 | L15: 2005-2009 | M15: Gatineau, Canada | N15: Open | O15: 1 | P15: 1 | R15: 0 | S15: Classification | T15: Spatio-temporal | U15: Gaussian mixture models | V15: Classification | W15: 0 | Y15: 0 | Z15: KL divergence;entropy | AA15: ICL;Entropy | AC15: Transportation
A16: Tonnelier, E.; Baskiotis, N.; Guigue, V.; Gallinari, P. | B16: Neurocomputing | C16: JUL 12 | D16: 2018 | E16: =VLOOKUP(default_1!F33,Hoja1!$AD$1:$AE$176,2,FALSE) -> 0 | F16: 10.1016/j.neucom.2017.12.067 | G16: P016 | H16: Subway | J16: 256000000 | K16: 91 | L16: 2015 | M16: Paris, France | N16: Closed | O16: 0 | P16: 1 | Q16: Network Status Updates | R16: 0 | S16: Anomaly detection | T16: Service disruptions/incidents | U16: Anomaly detection;Non-negative matrix factorization;Continuous user-based model | V16: Anomaly detection;Dimensionality reduction;Anomaly detection | W16: 0 | Y16: 0 | AA16: Std deviation;ROC curve;Accuracy;PPV | AC16: Transportation
A17: Yu, Wei; Bai, Hua; Chen, Jun; Yan, Xingchen | B17: IEEE Access | D17: 2019 | E17: =VLOOKUP(default_1!F29,Hoja1!$AD$1:$AE$176,2,FALSE) -> 4 | F17: 10.1109/ACCESS.2019.2943598 | G17: P017 | H17: Subway | J17: 1197147 | K17: 1 | L17: 2017 | M17: Nanjing, China | N17: Closed | O17: 1 | P17: 1 | R17: 0 | S17: Anomaly detection | T17: Passengers behaviour | U17: OD analysis | V17: OD matrix | W17: 0 | Y17: 1 | Z17: Inbound if next day;negative time taken;over 300 minutes;In and out same sattion in 0-3 minutes;In and out same station in 4-300 minutes;In and out same sation;swiping card over 8 times | AC17: Transportation
A18: Kapuku, Christian; Kho, Seung-Young; Kim, Dong-Kyu; Cho, Shin-Hyung | B18: Transp. Res. Record | C18: NOV | D18: 2021 | E18: =VLOOKUP(default_1!F38,Hoja1!$AD$1:$AE$176,2,FALSE) -> 4 | F18: 10.1177/03611981211045071 | G18: P018 | H18: Multimodal | I18: Subway;Bus | J18: 120400 | K18: 790 | L18: 2016-2018 | M18: Seoul, South Korea | N18: Closed | O18: 1 | P18: 1 | Q18: Travel data;Network | R18: 0 | S18: Performance indicators | T18: Mobility performance | U18: k-NN;Logistic regression;Support vector machine;Decision tree;Random forest;ReliefF | V18: Classification;Classification;Classification;Classification;Classification;Feature selection | W18: 0 | Y18: 1 | Z18: indicator bike-sharing travel time < Bus travel time;Bus trip travel time;Bus trip boarding time;Bus trip travel speed;Bus trip travel distance;Bike user’s gender;Bike user’s age;Bus detour factor: Bike travel distance - Bus traveldistance;The difference in travel speeds between bike-sharing and bus;Bike-sharing trip travel distance;Bike-sharing trip speed;The portion of the bike lane in the route;Total travel time for bike–transit intermodal trips;Total travel time for bus–transit intermodal trips | AA18: t-Value;Wilcoxon signed-rank test;TPR;TNR;PPV;FDR;FPR;AUC | AC18: Transportation
A19: Yen, Barbara T. H.; Mulley, Corinne; Tseng, Wen-Chun; Chiou, Yu-Chiun | B19: Case Stud. Transp. Policy | C19: SEP | D19: 2018 | E19: =VLOOKUP(default_1!F108,Hoja1!$AD$1:$AE$176,2,FALSE) -> 45 | F19: 10.1016/j.cstp.2018.01.005 | G19: P019 | H19: Multimodal | I19: Bus;Train;Ferry;Tram | J19: 15000000 | K19: 31 | L19: 2013 | M19: South East Queensland, Australia | N19: Closed | O19: 0 | P19: 1 | Q19: Social/Demographic/Economic;Layers | R19: 0 | S19: Performance indicators | T19: Transfer | U19: Latent class nested logit | V19: Classification | W19: 0 | Y19: 0 | Z19: Travel time;Travel cost;Travel zone;9 journey trip;Peak hour trip;Weekday trip;Commuter trip;Feeder bus stop density_ Heavy rail;Population density;Age (>65 years old);Students (>four years old);Employment;Public transport as main travel mode;Car number (more than two);High income (>1500/pw) | AA19: BIC;AIC;log likelihood ratios;number of parameters | AC19: Transportation
A20: Lee, Hasik; Park, Ho-Chul; Kho, Seung-Young; Kim, Dong-Kyu | B20: J. Transp. Geogr. | C20: OCT | D20: 2019 | E20: =VLOOKUP(default_1!F89,Hoja1!$AD$1:$AE$176,2,FALSE) -> 2 | F20: 10.1016/j.jtrangeo.2019.102546 | G20: P020 | H20: Multimodal | I20: Bus;Subway;Train | J20: 108311249 | K20: 7 | L20: 2017 | M20: Seoul, South Korea | N20: Closed | O20: 0 | P20: 0 | Q20: Social/Demographic/Economic;Land use;Transit Feed | R20: 0 | S20: Performance indicators | T20: Multimodal | U20: Transit competitiveness index | V20: Authors technique | W20: 0 | Y20: 1 | Z20: Transit competitiveness index | AA20: Correlation coefficient | AB20: QGIS | AC20: Transportation
A21: Hamedmoghadam, Homayoun; Vu, Hai L.; Jalili, Mahdi; Saberi, Meead; Stone, Lewi; Hoogendoorn, Serge | B21: Transp. Res. Pt. C-Emerg. Technol. | C21: AUG | D21: 2021 | E21: =VLOOKUP(default_1!F47,Hoja1!$AD$1:$AE$176,2,FALSE) -> 5 | F21: 10.1016/j.trc.2021.103210 | G21: P021 | H21: Multimodal | I21: Train;Tram;Bus | J21: 107576000 | K21: 61 | L21: 2017 | M21: Melbourne, Australia | N21: Closed | O21: 1 | P21: 1 | R21: 0 | S21: Origin-Destination | T21: OD Matrix Generation | U21: OD matrix;Random forest;Binary classification | V21: OD matrix;Classification;Classification | W21: 0 | Y21: 1 | Z21: ITT | AA21: Accuracy;Performance | AC21: Transportation
A22: Guzman, Luis A.; Beltran, Carlos; Bonilla, Jorge; Cardona, Santiago Gomez | B22: Transp. Res. Pt. A-Policy Pract. | C22: AUG | D22: 2021 | E22: =VLOOKUP(default_1!F45,Hoja1!$AD$1:$AE$176,2,FALSE) -> 7 | F22: 10.1016/j.tra.2021.06.018 | G22: P022 | H22: Bus | J22: 9300000 | K22: 3012 | L22: 2010-1018 | M22: Bogotá, Colombia | N22: Open | O22: 0 | P22: 0 | Q22: Travel data;Social/Demographic/Economic;Travel data;Social/Demographic/Economic | R22: 0 | S22: Performance indicators | T22: Fare | U22: Panel data model;Partitioning around medoids | V22: Panel analysis;Clustering | W22: 0 | Y22: 0 | AA22: t-Value | AB22: R | AC22: Transportation
A23: Rahbar, Mohadeseh; Hickman, Mark; Mesbah, Mahmoud; Tavassoli, Ahmad | B23: IEEE Trans. Intell. Transp. Syst. | C23: APR | D23: 2019 | E23: =VLOOKUP(default_1!F97,Hoja1!$AD$1:$AE$176,2,FALSE) -> 12 | F23: 10.1109/TITS.2018.2852726 | G23: P023 | H23: Multimodal | I23: Bus;Ferry;Train | J23: 189963 | K23: 31 | L23: 2013 | M23: South East Queensland, Australia | N23: Closed | O23: 0 | P23: 1 | Q23: Transit Feed;Meteorological;Network | R23: 0 | S23: Path planning/finding | T23: Route choice | U23: Bayesian Hierarchical;Markov chain Monte Carlo;Multinomial Logit | V23: Probability techniques;Probability techniques;Regression | W23: 0 | Y23: 1 | AA23: BIC;RMSE | AB23: R;JAGS | AC23: Transportation
A24: Zhu, Wei; Fan, Wei-li; Wahaballa, Amr M.; Wei, Jin | B24: Transportation | C24: DEC | D24: 2020 | E24: =VLOOKUP(default_1!F66,Hoja1!$AD$1:$AE$176,2,FALSE) -> 7 | F24: 10.1007/s11116-019-10040-8 | G24: P024 | H24: Train | J24: 44080649 | K24: 7 | L24: 2016 | M24: Beijing, China | N24: Closed | O24: 1 | P24: 1 | R24: 0 | S24: Path planning/finding | T24: Route choice | U24: Local outlier factor;Rodriguez–Laio 2014 | V24: Anomaly detection;Clustering | W24: 0 | Y24: 1 | Z24: OD absolute threshold;OD relative threshold;fastest travel time;slowest travel time | AA24: Thresholds | AC24: Transportation
A25: Zhang, Nan; Jia, Wei; Wang, Peihua; Dung, Chung-Hin; Zhao, Pengcheng; Leung, Kathy; Su, Boni; Cheng, Reynold; Li, Yuguo | B25: Cities | C25: MAY | D25: 2021 | E25: =VLOOKUP(default_1!F55,Hoja1!$AD$1:$AE$176,2,FALSE) -> 5 | F25: 10.1016/j.cities.2021.103139 | G25: P025 | H25: Train | J25: 272000000 | K25: 91 | L25: 2020 | M25: Hong Kong, China | N25: Closed | O25: 0 | P25: 0 | Q25: Social/Demographic/Economic;COVID-19;COVID-19;Population mobility;Regulation;Network;Travel data | R25: 0 | S25: Pattern analysis | T25: COVID-19 | U25: Descriptive statistics | V25: Descriptive statistics | W25: 0 | Y25: 1 | AA25: Correlation coefficient | AC25: Public health
A26: Rodriguez Gonzalez, Ana Belen; Wilby, Mark R.; Vinagre Diaz, Juan Jose; Fernandez Pozo, Ruben | B26: Sensors | C26: OCT | D26: 2021 | E26: =VLOOKUP(default_1!F37,Hoja1!$AD$1:$AE$176,2,FALSE) -> 13 | F26: 10.3390/s21196574 | G26: P026 | H26: Multimodal | I26: Subway;Train;Bus | J26: 5825614 | K26: 234 | L26: 2020 | M26: Fuenlabrada, Spain | N26: Open | O26: 0 | P26: 0 | Q26: Sensor data | R26: 0 | S26: Pattern analysis | T26: COVID-19 | U26: Regression Trees;Gaussian Process Regressor | V26: Regression;Regression | W26: 0 | Y26: 1 | AA26: MAPE | AB26: Matlab | AC26: Public health
A27: Qiu, Guo; Song, Rui; He, Shiwei; Xu, Wangtu; Jiang, Min | B27: IEEE Trans. Intell. Transp. Syst. | C27: SEP | D27: 2019 | E27: =VLOOKUP(default_1!F90,Hoja1!$AD$1:$AE$176,2,FALSE) -> 12 | F27: 10.1109/TITS.2018.2875466 | G27: P027 | H27: Bus | J27: 40000000 | K27: 5 | L27: 2015 | M27: Beijing, China | N27: Closed | O27: 1 | P27: 1 | R27: 0 | S27: Path planning/finding | T27: Custom routes | U27: P-DN;DBSCAN;k-means;Gaussian mixture models | V27: Clustering;Clustering;Clustering;Clustering | W27: 1 | X27: DBSCAN | Y27: 1 | AA27: CP;SP;DBI;DI;ARI;AMI | AB27: Matlab | AC27: Transportation
A28: El Mahrsi, Mohamed K.; Come, Etienne; Oukhellou, Latifa; Verleysen, Michel | B28: IEEE Trans. Intell. Transp. Syst. | C28: MAR | D28: 2017 | E28: =VLOOKUP(default_1!F122,Hoja1!$AD$1:$AE$176,2,FALSE) -> 0 | F28: 10.1109/TITS.2016.2600515 | G28: P028 | H28: Bus | J28: 5404096 | K28: 30 | L28: 2014 | M28: Rennes, France | N28: Open | O28: 1 | P28: 1 | R28: 0 | S28: Classification | T28: Spatio-temporal | U28: Poisson mixture;Mixture of unigrams model | V28: Clustering;Clustering | W28: 1 | X28: Count series clustering (Come and Oukhellou 2014) | Y28: 1 | AA28: log likelihood ratios;AIC;BIC | AC28: Transportation
A29: Ye, Pengyao; Ma, Yiqing | B29: Transp. Res. Record | C29: FEB | D29: 2023 | E29: =VLOOKUP(default_1!F14,Hoja1!$AD$1:$AE$176,2,FALSE) -> 2 | F29: 10.1177/03611981221111355 | G29: P029 | H29: Bus | J29: 96065229 | K29: 31 | L29: 2019 | M29: Chengdu, China | N29: Open | O29: 0 | P29: 1 | Q29: Layers | R29: 0 | S29: Pattern analysis | T29: Passenger | U29: Logistic regression;n-gram;DBSCAN | V29: Regression;Natural language processing;Clustering | W29: 1 | X29: n-gram (Zhao et al. 2018) | Y29: 1 | AA29: Accuracy | AC29: Transportation
A30: Zhao, Pengjun; Cao, Yushu | B30: Transp. Policy | C30: JUN | D30: 2020 | E30: =VLOOKUP(default_1!F76,Hoja1!$AD$1:$AE$176,2,FALSE) -> 20 | F30: 10.1016/j.tranpol.2020.03.006 | G30: P030 | H30: Subway | J30: 81763455 | K30: 7 | L30: 2015 | M30: Shanghai, China | N30: Closed | O30: 0 | P30: 0 | Q30: Social/Demographic/Economic | R30: 0 | S30: Pattern analysis | T30: Social/Economic/Demographic | U30: GWR;Ordinary least squares;k-means | V30: Regression;Regression;Clustering | W30: 1 | X30: Long and Thill 2015, Alexander et al. 2015 | Y30: 1 | AA30: VIF;Moran's I;R²;AIC;Correlation coefficient;t-Value;AIC | AB30: SQL | AC30: Socio-economic / demographic
A31: Cheng, Long; Huang, Jie; Jin, Tanhua; Chen, Wendong; Li, Aoyong; Witlox, Frank | B31: J. Transp. Geogr. | C31: FEB | D31: 2023 | E31: =VLOOKUP(default_1!F4,Hoja1!$AD$1:$AE$176,2,FALSE) -> 20 | F31: 10.1016/j.jtrangeo.2023.103545 | G31: P031 | H31: Bike | J31: 19720000 | K31: 30 | L31: 2017 | M31: Nanjing, China | N31: Closed | O31: 0 | P31: 0 | Q31: Social/Demographic/Economic;Social/Demographic/Economic;Layers;Layers;Land use;Layers;Network;Meteorological | R31: 0 | S31: Pattern analysis | T31: Multimodal | U31: Generalised additive mixed model | V31: Regression | W31: 0 | Y31: 0 | Z31: SBBS-metro integrated use, FFBS-metro integrated use, Population density, Employment density, Street connectivity, Road density, Land use mix3, Distance to CBD, Number of feeder bus lines, Rainfall, Temperature, Time of day, Day of week | AA31: estimated degree of freedom;R²;confidence intervals | AC31: Transportation
A32: Ji, Yanjie; Ma, Xinwei; He, Mingjia; Jin, Yuchuan; Yuan, Yufei | B32: J. Clean Prod. | C32: MAY 10 | D32: 2020 | E32: =VLOOKUP(default_1!F77,Hoja1!$AD$1:$AE$176,2,FALSE) -> 38 | F32: 10.1016/j.jclepro.2020.120110 | G32: P032 | H32: Bike | J32: 3233566 | K32: 7 | L32: 2017 | M32: Nanjing, China | N32: Closed | O32: 0 | P32: 0 | Q32: Land use | R32: 0 | S32: Performance indicators | T32: Mobility performance | U32: Ortegatong et al. 2013;Binary logistic model | V32: Classification;Regression | W32: 0 | Y32: 0 | Z32: User type;Riding distance;Riding time;Trips during morning peak hours;Trips during afternoon peak hours;Trips during off-peak hours;Trips on workdays;Trips on weekends;Working POI;Residential POI;Transit POI;Entertainment POI;Other POIs;Distance to CBD | AA32: VIF;pseudo-R² | AC32: Transportation
A33: Peng, Liqiang; Li, Qiang; Wang, Fei | B33: Multimedia Syst. | C33: APR | D33: 2023 | E33: =VLOOKUP(default_1!F17,Hoja1!$AD$1:$AE$176,2,FALSE) -> 13 | F33: 10.1007/s00530-022-00967-x | G33: P033 | H33: Multimodal | I33: Bus;Subway | J33: 30000000 | K33: 7 | M33: Singapore | N33: Closed | O33: 0 | P33: 0 | Q33: POI | R33: 0 | S33: Classification | T33: Social/Economic/Demographic | U33: Ranking Algorithm;Top-k neighbor;TF-IDF;LDA | V33: Ranking algorithm;Regression;Natural language processing;Natural language processing | W33: 0 | X33: PageRank (Page and Brin 1998) | Y33: 1 | AA33: Accuracy | AC33: Transportation
A34: Rodriguez Gonzalez, Ana Belen; Vinagre Diaz, Juan Jose; Wilby, Mark R.; Fernandez Pozo, Ruben | B34: Sensors | C34: JAN | D34: 2022 | E34: =VLOOKUP(default_1!F31,Hoja1!$AD$1:$AE$176,2,FALSE) -> 31 | F34: 10.3390/s22010017 | G34: P034 | H34: Multimodal | I34: Bus;Train;Tram;Subway | J34: 500000000 | K34: 120 | L34: 2018-2019 | M34: Madrid, Spain | N34: Closed | O34: 0 | P34: 1 | Q34: Network | R34: 0 | S34: Performance indicators | T34: Journey time | U34: OD matrix | V34: OD matrix | W34: 0 | Y34: 0 | AC34: Transportation
A35: Wang, Yun; Currim, Faiz; Ram, Sudha | B35: Inf. Syst. Res. | C35: JUN | D35: 2022 | E35: =VLOOKUP(default_1!F27,Hoja1!$AD$1:$AE$176,2,FALSE) -> 52 | F35: 10.1287/isre.2021.1072 | G35: P035 | H35: Bus | J35: 210000000 | K35: 214 | L35: 2014 | M35: Fortaleza, Brazil | N35: Open | O35: 0 | P35: 0 | Q35: POI;Meteorological | R35: 0 | S35: Pattern analysis | T35: Spatio-temporal | U35: Deep Learning of Spatiotemporal Patterns | V35: Deep learning | W35: 0 | X35: CNN;LSTM;NE;FNN | Y35: 1 | AA35: MAE;RMSE;SMAPE;Wilcoxon rank-sum test | AC35: Transportation
A36: Maeda, Takashi Nicholas; Shiode, Narushige; Zhong, Chen; Mori, Junichiro; Sakimoto, Tetsuo | B36: J. Big Data | C36: JAN 14 | D36: 2019 | E36: =VLOOKUP(default_1!F101,Hoja1!$AD$1:$AE$176,2,FALSE) -> 28 | F36: 10.1186/s40537-019-0168-5 | G36: P036 | H36: Train | J36: 1808915180 | K36: 730 | L36: 2013-2015 | M36: Kansai Area, Japan | N36: Closed | O36: 1 | P36: 1 | R36: 0 | S36: Pattern analysis | T36: Activity detection | U36: Extraction of Activity Types and Change Detection;Non-negative matrix factorization;Jensen-Shannon divergence | V36: Authors technique;Dimensionality reduction;Probability techniques | W36: 1 | X36: Fan et al. 2014 | Y36: 1 | AA36: Correlation coefficient | AC36: Urban planning
A37: Du, Bowen; Liu, Chuanren; Zhou, Wenjun; Hou, Zhenshan; Xiong, Hui | B37: IEEE Trans. Knowl. Data Eng. | C37: MAR 1 | D37: 2019 | E37: =VLOOKUP(default_1!F98,Hoja1!$AD$1:$AE$176,2,FALSE) -> 102 | F37: 10.1109/TKDE.2018.2834909 | G37: P037 | H37: Multimodal | I37: Bus;Subway | J37: 1700000000 | K37: 91 | L37: 2014 | M37: Beijing, China | N37: Closed | O37: 0 | P37: 0 | Q37: POI;Network Status Updates | R37: 0 | S37: Anomaly detection | T37: Passengers behaviour | U37: Suspect identification models;DBSCAN | V37: Authors technique;Clustering | W37: 0 | Y37: 0 | Z37: Travel Time;Frequency;Short-Distance Rides;Transitions among Functional Zones;Frequently Visited Regions;Deviation from the Social Norm;Historical Behaviours | AA37: PPV;TPR;F-Score | AB37: Java;Scala;Apache Spark | AC37: Transportation
A38: Yun, Hyunsoo; Lee, Eun Hak; Kim, Dong-Kyu; Cho, Shin-Hyung | B38: Transp. Res. Record | C38: NOV | D38: 2021 | E38: =VLOOKUP(default_1!F41,Hoja1!$AD$1:$AE$176,2,FALSE) -> 8 | F38: 10.1177/03611981211027562 | G38: P038 | H38: Multimodal | I38: Subway;Bus | J38: 20980000 | K38: 1 | L38: 2017 | M38: Seoul, South Korea | N38: Closed | O38: 1 | P38: 1 | R38: 0 | S38: Performance indicators | T38: Accessibility | U38: Accesibility Index;Jenks’ Natural Breaks | V38: Descriptive statistics;Clustering | W38: 0 | Y38: 1 | Z38: Accesibility Index | AC38: Urban planning
A39: Zhao, Zhan; Koutsopoulos, Haris N.; Zhao, Jinhua | B39: Transp. Res. Pt. C-Emerg. Technol. | C39: JUL | D39: 2020 | E39: =VLOOKUP(default_1!F11,Hoja1!$AD$1:$AE$176,2,FALSE) -> 20 | F39: 10.1016/j.trc.2020.102627 | G39: P039 | H39: Multimodal | I39: Subway;Tram;Train | J39: 3339187 | K39: 730 | M39: London, UK | N39: Closed | O39: 1 | P39: 1 | R39: 0 | S39: Activity estimation | T39: Activity estimation | U39: LDA | V39: Natural language processing | W39: 0 | Y39: 1 | AA39: log likelihood ratios;PP | AB39: Python;Cython | AC39: Transportation
A40: Lee, Gyeongjae; Choo, Sangho; Choi, Sungtaek; Lee, Hyangsook | B40: Sustainability | C40: JUN | D40: 2022 | E40: =VLOOKUP(default_1!F18,Hoja1!$AD$1:$AE$176,2,FALSE) -> 4 | F40: 10.3390/su14127431 | G40: P040 | H40: Bus | J40: 1856015 | K40: 92 | L40: 2020 | M40: Seoul, South Korea | N40: Closed | O40: 0 | P40: 0 | Q40: Travel data;Meteorological | R40: 0 | S40: Performance indicators | T40: Travel time | U40: Geo-conv Long Short-term Memory model | V40: Deep learning | W40: 1 | X40: 1D-CNN;LSTM | Y40: 0 | Z40: Set of stops;Stop i;The latitude of stop i;The longitude of stop i;The number of passengers getting on the target bus at the stop i;The number of passengers getting off the target bus at the stop i;The number of passengers on board when the target bus arrives at the stop i;The number of passengers getting on buses other than the target bus at bus stop i;The number of passengers getting off buses other than the target bus at bus stop i;The speed of the link to which the stop i belongs;The number of lanes of the link to which the stop i belongs;Temperature around the stop i;Precipitation around the stop i;Identity of the vehicle;The time slot of the day (1 min: 1);The day of week | AA40: RMSE;MAE;MAPE | AC40: Transportation
...

Sheet Hoja1
P1: Algorithm type | W1: Study Area | AD1: 10.1016/j.jtrangeo.2022.103415 | AE1: 11
P2: Clustering | Q2: Clustering | R2: {=_xlfn.UNIQUE(Q2:Q334)} -> Clustering | W2: Beijing, China | X2: {=_xlfn._xlws.SORT(_xlfn.UNIQUE(W2:W177))} -> Amsterdam, Netherlands | AD2: 10.1080/23249935.2022.2028929 | AE2: 4
C3: Passenger profiling algorithm | G3: {=_xlfn._xlws.SORT(_xlfn.UNIQUE(C3:C335))} -> Accesibility Index | P3: Authors algorithm | Q3: Authors algorithm | R3: Authors algorithm | W3: Taipei City, Taiwan | X3: Beer Sheva, Israel;Kiryat Gat, Israel | AD3: 10.1016/j.jtrangeo.2021.103046 | AE3: 23
C4: Time saving algorithm | G4: Agglomerative hierarchical clustering | P4: Regression | Q4: Regression | R4: Regression | W4: Nanjing, China | X4: Beijing, China | AD4: 10.1007/s00500-022-07025-8 | AE4: 6
C5: Generalised additive mixed model | G5: alighting estimation algorithm | P5: Regression | Q5: Regression | R5: OD matrix | W5: Beijing, China | X5: Bogotá, Colombia | AD5: 10.1016/j.urbmob.2022.100035 | AE5: 2
C6: Binomial logit model | G6: alighting stop inference algorithm | P6: OD matrix | Q6: OD matrix | R6: Stochastic modeling | W6: Lisbon, Portugal | X6: Brisbane, Australia | AD6: 10.1016/j.trc.2021.103267 | AE6: 2
C7: OD matrix | G7: Anomaly detection | P7: Stochastic modeling;Clustering | Q7: Stochastic modeling | R7: Optimization | W7: Seoul, South Korea | X7: Camp de Tarragona, Spain | AD7: 10.1016/j.tra.2021.02.007 | AE7: 23
C8: Hidden Markov Model | G8: ARIMA | P8: Authors algorithm;Regression | Q8: Clustering | R8: Language model | W8: Greater Toronto and Hamilton Area, Canada | X8: Changsha, China | AD8: 10.1016/j.compenvurbsys.2020.101517 | AE8: 23
C9: k-means | G9: Authors algorithm | P9: Optimization;Optimization;Clustering | Q9: Authors algorithm | R9: Descriptive statistics | W9: Daegu, South Korea | X9: Chengdu, China | AD9: 10.1080/23249935.2022.2079755 | AE9: 2
C10: Data fusion | G10: AVL, Fare and Schedule integration model | P10: Regression | Q10: Regression | R10: Deep learning | W10: Nanjing, China | X10: Copenhagen, Denmark | AD10: 10.1177/03611981221110229 | AE10: 0
C11: Multinomial logit model | G11: Bayesian Additive Model-Gaussian Process | P11: Language model | Q11: Optimization | R11: Ranking algorithm | W11: London, UK | X11: Curitiba, Brazil | AD11: 10.1109/TITS.2020.3043021 | AE11: 14
C12: Linear programming | G12: Bayesian Hierarchical | P12: Language model;Descriptive statistics | Q12: Optimization | R12: Probability model | W12: Wuhan, China | X12: Daegu, South Korea | AD12: 10.3390/s22010017 | AE12: 5
C13: Dynamic programming | G13: Bayesian model | P13: Deep learning;Deep learning;Deep learning | Q13: Clustering | R13: Dimensionality reduction | W13: Melbourne, Australia | X13: Davangere, India | AD13: 10.1155/2022/2080552 | AE13: 4
C14: Poisson distribution | G14: Bidirectional Long short-term memory | P14: Regression;Language model;Clustering | Q14: Regression | R14: Anomaly detection | W14: Chengdu, China | X14: Denmark | AD14: 10.1177/03611981211027562 | AE14: 4
C15: Gradient boosting | G15: Binary classification | P15: Regression | Q15: Language model | R15: Classification | W15: Chengdu, China | X15: Eastern Denmark, Denmark | AD15: 10.3390/s21196574 | AE15: 20
... C37: Probability distribution functions | G37: DBSACN | P37: Regression;Regression | Q37: Regression | R37: Cluster | W37: Fuenlabrada, Spain | X37: Madrid, Spain | AD37: 10.1016/j.tra.2023.103747 | AE37: 5
C38: Naive Bayes | G38: DBSCAN | P38: Classification;Classification;Classification;Classification;Classification;Feature selection | Q38: Probability model | W38: Seoul, South Korea | X38: Melbourne, Australia | AD38: 10.3846/transport.2020.14159 | AE38: 3
C39: Probability model | G39: Decision tree | P39: Regression;Regression | Q39: Clustering | W39: South-West Scania, Sweden | X39: Montréal, Canada | AD39: 10.1061/JTEPBS.TEENG-7634 | AE39: 2
C40: DBSCAN | G40: Decision Tree diagram | P40: Game theory;Classification;Classification;Classification | Q40: Deep learning | W40: Beer Sheva, Israel;Kiryat Gat, Israel | X40: Nanjing, China | AD40: 10.1016/j.trc.2022.103790 | AE40: 6
C41: STGGA | G41: Deep learning | P41: Descriptive statistics;Clustering | Q41: Clustering | W41: Seoul, South Korea | X41: New York, USA | AD41: 10.1016/j.trc.2022.103559 | AE41: 3
C42: k-means | G42: Deep Learning of Spatiotemporal Patterns | P42: Clustering;Clustering;OD matrix | Q42: Deep learning | W42: Beijing, China | X42: Osaka, Japan | AD42: 10.1016/j.tbs.2023.100587 | AE42: 5
C43: Convolutional neural networks | G43: Densely Connected Convolutional Networks | P43: Authors algorithm;Forecasting;trip-chaining algorithm;Anomaly detection | Q43: Deep learning | W43: Santander, Spain | X43: Paris, France | AD43: 10.1109/TITS.2020.2983853 | AE43: 13
C44: Densely Connected Convolutional Networks | G44: Descriptive statistics | P44: Probability model;Regression | Q44: Clustering | W44: London, UK | X44: Porto, Portugal | AD44: 10.1177/03611981211045071 | AE44: 4
C45: Spatial cluster partitioning algorithm | G45: Direct Ridership Model | P45: Panel analysis;Clustering | Q45: Dimensionality reduction | W45: Bogotá, Colombia | X45: Qingdao, China | AD45: 10.1016/j.tbs.2023.100620 | AE45: 7
C46: Dynamic mode decomposition | G46: Dwell time model | P46: Authors algorithm | Q46: Deep learning | W46: Shenzhen, China | X46: Rennes, France | AD46: 10.1016/j.tra.2022.09.010 | AE46: 4
C47: Deep Learning of Spatiotemporal Patterns | G47: Dynamic factor model | P47: OD matrix;Classifictaion;Classifictaion | Q47: Regression | W47: Melbourne, Australia | X47: Riga, Latvia | AD47: 10.1016/j.scs.2021.103111 | AE47: 17
C48: Multinomial logit | G48: Dynamic Genetic Algorithm | P48: Classification | Q48: OD matrix | W48: Seoul, South Korea | X48: Rotterdam, Netherlands | AD48: 10.1080/23249935.2021.2005180 | AE48: 7
C49: OD analysis | G49: Dynamic mode decomposition | P49: Clustering | Q49: Optimization | W49: Shenzhen, China | X49: Santander, Spain | AD49: 10.1016/j.cities.2021.103139 | AE49: 123
... C76: Logistic Regression | G76: GWNBR | P76: Regression;Regression;Clustering | Q76: Classification | W76: Shanghai, China | X76: Zhuhai, China | AD76: 10.1016/j.trc.2021.103467 | AE76: 15
C77: XGBoost | G77: GWR | P77: Classification;Regression | Q77: Descriptive statistics | W77: Nanjing, China | AD77: 10.1080/21680566.2023.2226824 | AE77: 0
C78: Accesibility Index | G78: Hamming algorithm | P78: trip-chaining algorithm;Descriptive statistics | Q78: Clustering | W78: São Paulo, Brazil | AD78: 10.1016/j.trc.2021.103307 | AE78: 11
C79: Jenks’ Natural Breaks | G79: HDDC | P79: Time series analysis;Regression;Regression | Q79: Clustering | W79: Nanjing, China | AD79: 10.1186/s12544-021-00488-0 | AE79: 48
C80: k-means++ | G80: Hidden Markov Model | P80: Clustering;Clustering | Q80: Clustering | W80: Beijing, China | AD80: 10.3390/ijerph18052711 | AE80: 8
C81: group mobility correlation | G81: Hierarchical mixture model | P81: Neural networks;Deep learning | Q81: OD matrix | W81: South East Queensland, Australia | AD81: 10.1016/j.jtrangeo.2021.103242 | AE81: 15
C82: individual correlation | G82: HIERARCHICHAL AGGLOMERATIVE CLUSTERING | P82: Clustering;Genetic algorithm | Q82: Authors algorithm | W82: Zhongshan, China | AD82: 10.1007/s12469-022-00309-0 | AE82: 0
C83: AVL, Fare and Schedule integration model | G83: Historical average time series | P83: Clustering | Q83: Forecasting | W83: Nanjing, China | AD83: 10.1061/JTEPBS.0000721 | AE83: 9
C84: Dwell time model | G84: ID-based dataset clustering | P84: OD matrix | Q84: trip-chaining algorithm | W84: Porto, Portugal | AD84: 10.1016/j.trc.2021.103210 | AE84: 10
C85: trip-chaining model | G85: IDW interpolation | P85: Descriptive statistics | Q85: Anomaly detection | W85: Nanjing, China | AD85: 10.1155/2021/9966794 | AE85: 5
C86: Anomaly detection | G86: individual correlation | P86: Deep learning | Q86: Probability model | W86: London, UK | AD86: 10.1109/ACCESS.2021.3107833 | AE86: 2
C87: Passenger to train assignment | G87: Inner-PNN-AECM | P87: Clustering;Clustering | Q87: Regression | W87: Riga, Latvia | AD87: 10.1016/j.tbs.2021.09.006 | AE87: 16
...
